<?xml version="1.0" ?>
<!-- =================================================================================== -->
<!-- |    This document was autogenerated by xacro from darias_clean.xacro             | -->
<!-- |    EDITING THIS FILE BY HAND IS NOT RECOMMENDED                                 | -->
<!-- =================================================================================== -->
<robot name="darias">
  <!-- all masses and inertias are not really adjusted to darias by now still need to do this sometime -->
  <!-- so by now this model is mainly just a kinematic one -->
  <!-- use 1 for true and 0 for false ,yet the controller can't compensate gravity - why ? -->
  <!-- length is along the y-axis! -->
  <!-- the mass values and inertia may not be completly correct as the moment so this model should just be used as a kinematic one now-->
  <!--
  <material name="DarkGrey"><color rgba="0.3 0.3 0.3 1.0"/></material>
  <material name="Black"><color rgba="0 0 0 1.0"/></material>
  <material name="Grey"><color rgba="0.7 0.7 0.7 1.0"/></material>
  <material name="Blue"><color rgba="0.0 0.0 0.8 1.0"/></material>
  <material name="HandGray"><color rgba="0.953 0.996 0.694 1.0"/></material>
  -->
  <!-- Darias base (basically just a box on which the arms are mounted on) -->
  <material name="white_transparent">
    <color rgba="0.98 0.94 0.84 .3"/>
  </material>
  <link name="world"/>
  <joint name="fixed" type="fixed">
    <origin rpy="0.0 0.0 0.0" xyz="0.0 0.0 1.307"/>
    <parent link="world"/>
    <child link="darias"/>
  </joint>
  <link name="darias">
    <inertial>
      <mass value="200.0"/>
      <origin rpy="0 0 0" xyz="0 0 0.15"/>
      <inertia ixx="1.8210927083333333" ixy="0" ixz="0" iyy="0.7083333333333335" iyz="0" izz="2.4460927083333335"/>
    </inertial>
    <visual>
      <origin rpy="0 0 0" xyz="-0.1 0 -0.472"/>
      <geometry>
        <box size="0.2 0.2 1.5"/>
      </geometry>
      <material name="DarkGrey"/>
    </visual>
    <collision>
      <origin rpy="0 0 0" xyz="-0.1 0 -0.472"/>
      <geometry>
        <box size="0.2 0.2 1.5"/>
      </geometry>
    </collision>
  </link>
  <gazebo reference="darias">
    <material value="Gazebo/Black"/>
    <turnGravityOff>0</turnGravityOff>
    <!-- use gravity for the base even if disabled for the arms in order to prevent darias from falling-->
  </gazebo>
  <material name="Blue_pastel">
    <color rgba="0.482 0.8 0.894 1."/>
    <!--<color rgba="0.4 0.58 0.1 1."/>-->
  </material>
  <material name="white_clean">
    <color rgba="0.98 0.94 0.84 1."/>
  </material>
  <!-- base_joint -->
  <joint name="darias_R_base_joint" type="fixed">
    <origin rpy="1.570796 -1.570796 0.523598776" xyz="-0.11 -0.06 0.193"/>
    <parent link="darias"/>
    <child link="calib_R_base_link"/>
  </joint>
  <link name="calib_R_base_link">
    <inertial>
      <mass value="1.0"/>
      <origin rpy="0 0 0" xyz="0 0 0.055"/>
      <inertia ixx="0.001908333333333333" ixy="0" ixz="0" iyy="0.0018" iyz="0" izz="0.001908333333333333"/>
    </inertial>
    <visual>
      <origin rpy="0 0 0" xyz="0 0 0"/>
      <geometry>
        <mesh filename="package://darias_description/meshes/arm/convex/arm_base_convex.stl"/>
      </geometry>
      <material name="Blue_pastel"/>
    </visual>
    <collision>
      <origin rpy="0 0 0" xyz="0 0 0"/>
      <geometry>
        <mesh filename="package://darias_description/meshes/arm/convex/arm_base_convex.stl"/>
      </geometry>
    </collision>
  </link>
  <gazebo reference="calib_R_base_link">
    <material value="Gazebo/Blue"/>
    <turnGravityOff>1</turnGravityOff>
  </gazebo>
  <!-- SFE joint (first joint of the arm )-->
  <joint name="R_SFE" type="revolute">
    <!-- former revolute -->
    <origin rpy="0 0 0" xyz="0 0 0.11"/>
    <axis xyz="0 0 1"/>
    <limit effort="10000.0" lower="-2.967059" upper="2.967059" velocity="1.9198621771937625"/>
    <!-- 204 -->
    <safety_controller k_position="100" k_velocity="2" soft_lower_limit="-2.9321531433504737" soft_upper_limit="2.9321531433504737"/>
    <dynamics damping="0.1"/>
    <parent link="calib_R_base_link"/>
    <child link="R_1_link"/>
  </joint>
  <link name="R_1_link">
    <inertial>
      <mass value="1.0"/>
      <origin rpy="0 0 0" xyz="0 0 0.130"/>
      <inertia ixx="0.006833333333333334" ixy="0" ixz="0" iyy="0.0014999999999999998" iyz="0" izz="0.005933333333333335"/>
    </inertial>
    <visual>
      <origin rpy="0 0 3.141592653589793" xyz="0 0 0"/>
      <geometry>
        <mesh filename="package://darias_description/meshes/arm/convex/arm_segment_a_convex.stl"/>
      </geometry>
      <material name="Blue_pastel"/>
    </visual>
    <collision>
      <origin rpy="0 0 3.141592653589793" xyz="0 0 0"/>
      <geometry>
        <mesh filename="package://darias_description/meshes/arm/convex/arm_segment_a_convex.stl"/>
      </geometry>
    </collision>
  </link>
  <gazebo reference="R_1_link">
    <material value="Gazebo/Blue"/>
    <turnGravityOff>1</turnGravityOff>
  </gazebo>
  <transmission name="R_0_trans">
    <type>transmission_interface/SimpleTransmission</type>
    <joint name="R_SFE">
      <hardwareInterface>EffortJointInterface</hardwareInterface>
    </joint>
    <actuator name="R_0_motor">
      <mechanicalReduction>1.0</mechanicalReduction>
    </actuator>
  </transmission>
  <!-- SAA joint (second joint of the arm )-->
  <joint name="R_SAA" type="revolute">
    <origin rpy="0 0 0" xyz="0 0 0.20"/>
    <axis xyz="0 -1 0"/>
    <limit effort="10000.0" lower="-2.094395" upper="2.094395" velocity="1.9198621771937625"/>
    <!-- effort 306 -->
    <safety_controller k_position="100" k_velocity="2" soft_lower_limit="-2.0594885173533086" soft_upper_limit="2.0594885173533086"/>
    <dynamics damping="0.1"/>
    <parent link="R_1_link"/>
    <child link="R_2_link"/>
  </joint>
  <link name="R_2_link">
    <inertial>
      <mass value="1.0"/>
      <origin rpy="0 0 0" xyz="0 0.06 0.07"/>
      <inertia ixx="0.006833333333333334" ixy="0" ixz="0" iyy="0.0014999999999999998" iyz="0" izz="0.005933333333333335"/>
    </inertial>
    <visual>
      <origin rpy="3.141592653589793 0 3.141592653589793" xyz="0 0 0.2"/>
      <geometry>
        <mesh filename="package://darias_description/meshes/arm/convex/arm_segment_b_convex.stl"/>
      </geometry>
      <material name="Blue_pastel"/>
    </visual>
    <collision>
      <origin rpy="3.141592653589793 0 3.141592653589793" xyz="0 0 0.2"/>
      <geometry>
        <mesh filename="package://darias_description/meshes/arm/convex/arm_segment_b_convex.stl"/>
      </geometry>
    </collision>
  </link>
  <gazebo reference="R_2_link">
    <material value="Gazebo/Blue"/>
    <turnGravityOff>1</turnGravityOff>
  </gazebo>
  <transmission name="R_1_trans">
    <type>transmission_interface/SimpleTransmission</type>
    <joint name="R_SAA">
      <hardwareInterface>EffortJointInterface</hardwareInterface>
    </joint>
    <actuator name="R_1_motor">
      <mechanicalReduction>1.0</mechanicalReduction>
    </actuator>
  </transmission>
  <!-- HR joint (third joint of the arm )-->
  <joint name="R_HR" type="revolute">
    <origin rpy="0 0 0" xyz="0 0 0.20"/>
    <axis xyz="0 0 1"/>
    <limit effort="10000.0" lower="-2.967059" upper="2.967059" velocity="2.2689280275926285"/>
    <!-- 204 -->
    <safety_controller k_position="100" k_velocity="2" soft_lower_limit="-2.9321531433504737" soft_upper_limit="2.9321531433504737"/>
    <dynamics damping="0.1"/>
    <parent link="R_2_link"/>
    <child link="R_3_link"/>
  </joint>
  <link name="R_3_link">
    <inertial>
      <mass value="1.0"/>
      <origin rpy="0 0 0" xyz="0 0.06 0.130"/>
      <inertia ixx="0.006833333333333334" ixy="0" ixz="0" iyy="0.0014999999999999998" iyz="0" izz="0.005933333333333335"/>
    </inertial>
    <visual>
      <origin rpy="0 0 0" xyz="0 0 0"/>
      <geometry>
        <mesh filename="package://darias_description/meshes/arm/convex/arm_segment_a_convex.stl"/>
      </geometry>
      <material name="Blue_pastel"/>
    </visual>
    <collision>
      <origin rpy="0 0 0" xyz="0 0 0"/>
      <geometry>
        <mesh filename="package://darias_description/meshes/arm/convex/arm_segment_a_convex.stl"/>
      </geometry>
    </collision>
  </link>
  <gazebo reference="R_3_link">
    <material value="Gazebo/Blue"/>
    <turnGravityOff>1</turnGravityOff>
  </gazebo>
  <transmission name="R_2_trans">
    <type>transmission_interface/SimpleTransmission</type>
    <joint name="R_HR">
      <hardwareInterface>EffortJointInterface</hardwareInterface>
    </joint>
    <actuator name="R_2_motor">
      <mechanicalReduction>1.0</mechanicalReduction>
    </actuator>
  </transmission>
  <!-- EB joint (fourth joint of the arm )-->
  <joint name="R_EB" type="revolute">
    <origin rpy="0 0 0" xyz="0 0 0.20"/>
    <axis xyz="0 1 0"/>
    <limit effort="10000.0" lower="-2.094395" upper="2.094395" velocity="2.2689280275926285"/>
    <!-- 306 -->
    <safety_controller k_position="100" k_velocity="2" soft_lower_limit="-2.0594885173533086" soft_upper_limit="2.0594885173533086"/>
    <dynamics damping="0.1"/>
    <parent link="R_3_link"/>
    <child link="R_4_link"/>
  </joint>
  <link name="R_4_link">
    <inertial>
      <mass value="1.0"/>
      <origin rpy="0 0 0" xyz="0 -0.06 0.07"/>
      <inertia ixx="0.006833333333333334" ixy="0" ixz="0" iyy="0.0014999999999999998" iyz="0" izz="0.005933333333333335"/>
    </inertial>
    <visual>
      <origin rpy="0 3.141592653589793 3.141592653589793" xyz="0 0 0.2"/>
      <geometry>
        <mesh filename="package://darias_description/meshes/arm/convex/arm_segment_b_convex.stl"/>
      </geometry>
      <material name="Blue_pastel"/>
    </visual>
    <collision>
      <origin rpy="0 3.141592653589793 3.141592653589793" xyz="0 0 0.2"/>
      <geometry>
        <mesh filename="package://darias_description/meshes/arm/convex/arm_segment_b_convex.stl"/>
      </geometry>
    </collision>
  </link>
  <gazebo reference="R_4_link">
    <material value="Gazebo/Blue"/>
    <turnGravityOff>1</turnGravityOff>
  </gazebo>
  <transmission name="R_3_trans">
    <type>transmission_interface/SimpleTransmission</type>
    <joint name="R_EB">
      <hardwareInterface>EffortJointInterface</hardwareInterface>
    </joint>
    <actuator name="R_3_motor">
      <mechanicalReduction>1.0</mechanicalReduction>
    </actuator>
  </transmission>
  <!-- WR joint (fifth joint of the arm )-->
  <joint name="R_WR" type="revolute">
    <origin rpy="0 0 0" xyz="0 0 0.20"/>
    <axis xyz="0 0 1"/>
    <limit effort="10000.0" lower="-2.967059" upper="2.967059" velocity="2.2689280275926285"/>
    <!-- 204 -->
    <safety_controller k_position="100" k_velocity="2" soft_lower_limit="-2.9321531433504737" soft_upper_limit="2.9321531433504737"/>
    <dynamics damping="0.1"/>
    <parent link="R_4_link"/>
    <child link="R_5_link"/>
  </joint>
  <link name="R_5_link">
    <inertial>
      <mass value="1.0"/>
      <origin rpy="0 0 0" xyz="0 0 0.124"/>
      <inertia ixx="0.006325333333333333" ixy="0" ixz="0" iyy="0.0014999999999999998" iyz="0" izz="0.005425333333333333"/>
    </inertial>
    <visual>
      <origin rpy="0 0 3.141592653589793" xyz="0 0 0"/>
      <geometry name="R_5_geom">
        <mesh filename="package://darias_description/meshes/arm/convex/arm_segment_last_convex.stl"/>
      </geometry>
      <material name="Blue_pastel"/>
    </visual>
    <collision>
      <origin rpy="0 0 3.141592653589793" xyz="0 0 0"/>
      <geometry>
        <mesh filename="package://darias_description/meshes/arm/convex/arm_segment_last_convex.stl"/>
      </geometry>
    </collision>
  </link>
  <gazebo reference="R_5_link">
    <material value="Gazebo/Blue"/>
    <turnGravityOff>1</turnGravityOff>
  </gazebo>
  <transmission name="R_4_trans">
    <type>transmission_interface/SimpleTransmission</type>
    <joint name="R_WR">
      <hardwareInterface>EffortJointInterface</hardwareInterface>
    </joint>
    <actuator name="R_4_motor">
      <mechanicalReduction>1.0</mechanicalReduction>
    </actuator>
  </transmission>
  <!-- WFE joint (six joint of the arm )-->
  <joint name="R_WFE" type="revolute">
    <origin rpy="0 0 0" xyz="0 0 0.19"/>
    <axis xyz="0 -1 0"/>
    <limit effort="10000.0" lower="-2.094395" upper="2.094395" velocity="3.141592653589793"/>
    <!-- 306 -->
    <safety_controller k_position="100" k_velocity="2" soft_lower_limit="-2.0594885173533086" soft_upper_limit="2.0594885173533086"/>
    <dynamics damping="0.1"/>
    <parent link="R_5_link"/>
    <child link="R_6_link"/>
  </joint>
  <link name="R_6_link">
    <inertial>
      <mass value="1.0"/>
      <origin rpy="0 0 0" xyz="0 0 0.0625"/>
      <inertia ixx="0.0026041666666666665" ixy="0" ixz="0" iyy="0.0026041666666666665" iyz="0" izz="0.0026041666666666665"/>
    </inertial>
    <visual>
      <origin rpy="0 0 3.141592653589793" xyz="0 0 0"/>
      <geometry>
        <mesh filename="package://darias_description/meshes/arm/convex/arm_wrist_convex.stl"/>
      </geometry>
      <material name="white_clean"/>
    </visual>
    <collision>
      <origin rpy="0 0 3.141592653589793" xyz="0 0 0"/>
      <geometry>
        <mesh filename="package://darias_description/meshes/arm/convex/arm_wrist_convex.stl"/>
      </geometry>
    </collision>
  </link>
  <gazebo reference="R_6_link">
    <material value="Gazebo/White"/>
    <turnGravityOff>1</turnGravityOff>
  </gazebo>
  <transmission name="R_5_trans">
    <type>transmission_interface/SimpleTransmission</type>
    <joint name="R_WFE">
      <hardwareInterface>EffortJointInterface</hardwareInterface>
    </joint>
    <actuator name="R_5_motor">
      <mechanicalReduction>1.0</mechanicalReduction>
    </actuator>
  </transmission>
  <!-- WAA joint (seventh joint of the arm )
TODO: check effort limit +204-->
  <joint name="R_WAA" type="revolute">
    <origin rpy="0 0 0" xyz="0.0 0 0.078"/>
    <axis xyz="0 0 1"/>
    <limit effort="10204.0" lower="-2.967059" upper="2.967059" velocity="3.141592653589793"/>
    <safety_controller k_position="100" k_velocity="2" soft_lower_limit="-2.9321531433504737" soft_upper_limit="2.9321531433504737"/>
    <dynamics damping="0.1"/>
    <parent link="R_6_link"/>
    <child link="R_endeffector_link"/>
  </joint>
  <transmission name="R_6_trans">
    <type>transmission_interface/SimpleTransmission</type>
    <joint name="R_WAA">
      <hardwareInterface>EffortJointInterface</hardwareInterface>
    </joint>
    <actuator name="R_6_motor">
      <mechanicalReduction>1.0</mechanicalReduction>
    </actuator>
  </transmission>
  <!-- the inertial here needs too be modified as this link actually has no real mass but ros_control needs an inertial...-->
  <link name="R_endeffector_link">
    <inertial>
      <mass value="1"/>
      <origin rpy="0 0 0" xyz="0 0 0.0625"/>
      <inertia ixx="0.0026041666666666665" ixy="0" ixz="0" iyy="0.0026041666666666665" iyz="0" izz="0.0026041666666666665"/>
    </inertial>
  </link>
  <gazebo reference="R_endeffector_link">
    <material value="Gazebo/White"/>
    <turnGravityOff>1</turnGravityOff>
  </gazebo>
  <!-- gazebo plugin for ros control -->
  <gazebo>
    <plugin filename="libgazebo_ros_control.so" name="gazebo_ros_control">
      <robotNamespace>/darias</robotNamespace>
    </plugin>
  </gazebo>
</robot>
