<?xml version="1.0" ?>
<!-- =================================================================================== -->
<!-- |    This document was autogenerated by xacro from darias.urdf.xacro              | -->
<!-- |    EDITING THIS FILE BY HAND IS NOT RECOMMENDED                                 | -->
<!-- =================================================================================== -->
<robot name="darias" xmlns:controller="http://playerstage.sourceforge.net/gazebo/xmlschema/#controller" xmlns:interface="http://playerstage.sourceforge.net/gazebo/xmlschema/#interface" xmlns:sensor="http://playerstage.sourceforge.net/gazebo/xmlschema/#sensor" xmlns:xacro="http://www.ros.org/wiki/xacro">
  <!-- the mass values and inertia may not be completly correct as the moment so this model should just be used as a kinematic one now-->
  <material name="DarkGrey">
    <color rgba="0.3 0.3 0.3 1.0"/>
  </material>
  <material name="Black">
    <color rgba="0 0 0 1.0"/>
  </material>
  <material name="Grey">
    <color rgba="0.7 0.7 0.7 1.0"/>
  </material>
  <material name="Blue">
    <color rgba="0.0 0.0 0.8 1.0"/>
  </material>
  <material name="HandGray">
    <color rgba="0.953 0.996 0.694 1.0"/>
  </material>
  <!-- offset values for left and right arm, triangle forms 60 degree, offset over tabel: offset from base top: -->
  <!-- not used now need to measure offset-->
  <!-- not used now-->
  <!-- Darias base (basically just a box on which the arms are mounted on) -->
  <link name="world"/>
   <joint name="fixed" type="fixed">
   <origin rpy="0.0 0.0 0.0" xyz="0.0 0.0 1.307 "/>
   <parent link="world"/>
   <child link="darias"/>
   </joint>
  <link name="darias">
    <inertial>
      <mass value="200.0"/>
      <origin rpy="0 0 0" xyz="0 0 0.15"/>
      <!-- need to check all this inertia stuff -->
      <inertia ixx="2.38541666667" ixy="0" ixz="0" iyy="0.708333333333" iyz="0" izz="3.01041666667"/>
    </inertial>
    <visual>
      <origin rpy="0 0 0" xyz="-0.1 0 -0.472"/>
      <geometry>
        <box size="0.2 0.2 1.5"/>
      </geometry>
      <material name="DarkGrey"/>
    </visual>
    <collision>
      <origin rpy="0 0 0" xyz="-0.1 0 -0.472"/>
      <geometry>
        <box size="0.2 0.2 1.5"/>
      </geometry>
    </collision>
  </link>
  <gazebo reference="darias">
    <material value="Gazebo/Black"/>
    <turnGravityOff>0</turnGravityOff>
    <!-- use gravity for the base even if disabled for the arms in order to prevent darias from falling-->
  </gazebo>
  <!-- Darias right arm -->
  <joint name="darias_R_base" type="fixed">
    <origin rpy="1.570796 -1.570796 0.523598776" xyz="-0.11 -0.06 0.193"/>
    <parent link="darias"/>
    <child link="calib_R_base_link"/>
  </joint>
  <link name="calib_R_base_link">
    <inertial>
      <mass value="1.0"/>
      <origin rpy="0 0 0" xyz="0 0 0.055"/>
      <inertia ixx="0.00190833333333" ixy="0" ixz="0" iyy="0.0018" iyz="0" izz="0.00190833333333"/>
    </inertial>
    <visual>
      <origin rpy="0 0 0" xyz="0 0 0"/>
      <geometry>
        <mesh filename="package://darias_description/meshes/arm/convex/arm_base_convex.stl"/>
      </geometry>
      <material name="Blue"/>
    </visual>
    <collision>
      <origin rpy="0 0 0" xyz="0 0 0"/>
      <geometry>
        <mesh filename="package://darias_description/meshes/arm/convex/arm_base_convex.stl"/>
      </geometry>
    </collision>
  </link>
  <gazebo reference="calib_R_base_link">
    <material value="Gazebo/Blue"/>
    <turnGravityOff>1</turnGravityOff>
  </gazebo>
  <joint name="R_SFE" type="revolute">
    <!-- former revolute -->
    <origin rpy="0 0 0" xyz="0 0 0.11"/>
    <axis xyz="0 0 1"/>
    <limit effort="10000.0" lower="-2.967059" upper="2.967059" velocity="1.91986217719"/>
    <!-- 204 -->
    <safety_controller k_position="100" k_velocity="2" soft_lower_limit="-2.93215314335" soft_upper_limit="2.93215314335"/>
    <dynamics damping="0.1"/>
    <parent link="calib_R_base_link"/>
    <child link="R_1_link"/>
  </joint>
  <link name="R_1_link">
    <inertial>
      <mass value="1.0"/>
      <origin rpy="0 0 0" xyz="0 0 0.130"/>
      <inertia ixx="0.00683333333333" ixy="0" ixz="0" iyy="0.0015" iyz="0" izz="0.00593333333333"/>
    </inertial>
    <visual>
      <origin rpy="0 0 3.14159265359" xyz="0 0 0"/>
      <geometry>
        <mesh filename="package://darias_description/meshes/arm/convex/arm_segment_a_convex.stl"/>
      </geometry>
      <material name="Blue"/>
    </visual>
    <collision>
      <origin rpy="0 0 3.14159265359" xyz="0 0 0"/>
      <geometry>
        <mesh filename="package://darias_description/meshes/arm/convex/arm_segment_a_convex.stl"/>
      </geometry>
    </collision>
  </link>
  <gazebo reference="R_1_link">
    <material value="Gazebo/Blue"/>
    <turnGravityOff>1</turnGravityOff>
  </gazebo>
  <transmission name="R_0_trans">
    <type>transmission_interface/SimpleTransmission</type>
    <joint name="R_SFE">
      <hardwareInterface>EffortJointInterface</hardwareInterface>
    </joint>
    <actuator name="R_0_motor">
      <mechanicalReduction>1</mechanicalReduction>
    </actuator>
  </transmission>
  <joint name="R_SAA" type="revolute">
    <origin rpy="0 0 0" xyz="0 0 0.20"/>
    <axis xyz="0 -1 0"/>
    <limit effort="10000.0" lower="-2.094395" upper="2.094395" velocity="1.91986217719"/>
    <!-- effort 306 -->
    <safety_controller k_position="100" k_velocity="2" soft_lower_limit="-2.05948851735" soft_upper_limit="2.05948851735"/>
    <dynamics damping="0.1"/>
    <parent link="R_1_link"/>
    <child link="R_2_link"/>
  </joint>
  <link name="R_2_link">
    <inertial>
      <mass value="1.0"/>
      <origin rpy="0 0 0" xyz="0 0.06 0.07"/>
      <inertia ixx="0.00683333333333" ixy="0" ixz="0" iyy="0.0015" iyz="0" izz="0.00593333333333"/>
    </inertial>
    <visual>
      <origin rpy="3.14159265359 0 3.14159265359" xyz="0 0 0.2"/>
      <geometry>
        <mesh filename="package://darias_description/meshes/arm/convex/arm_segment_b_convex.stl"/>
      </geometry>
      <material name="Blue"/>
    </visual>
    <collision>
      <origin rpy="3.14159265359 0 3.14159265359" xyz="0 0 0.2"/>
      <geometry>
        <mesh filename="package://darias_description/meshes/arm/convex/arm_segment_b_convex.stl"/>
      </geometry>
    </collision>
  </link>
  <gazebo reference="R_2_link">
    <material value="Gazebo/Blue"/>
    <turnGravityOff>1</turnGravityOff>
  </gazebo>
  <transmission name="R_1_trans">
    <type>transmission_interface/SimpleTransmission</type>
    <joint name="R_SAA">
      <hardwareInterface>EffortJointInterface</hardwareInterface>
    </joint>  
    <actuator name="R_1_motor">
      
      <mechanicalReduction>1</mechanicalReduction>
    </actuator>
  </transmission>
  <joint name="R_HR" type="revolute">
    <origin rpy="0 0 0" xyz="0 0 0.20"/>
    <axis xyz="0 0 1"/>
    <limit effort="10000.0" lower="-2.967059" upper="2.967059" velocity="2.26892802759"/>
    <!-- 204 -->
    <safety_controller k_position="100" k_velocity="2" soft_lower_limit="-2.93215314335" soft_upper_limit="2.93215314335"/>
    <dynamics damping="0.1"/>
    <parent link="R_2_link"/>
    <child link="R_3_link"/>
  </joint>
  <link name="R_3_link">
    <inertial>
      <mass value="1.0"/>
      <origin rpy="0 0 0" xyz="0 0.06 0.130"/>
      <inertia ixx="0.00683333333333" ixy="0" ixz="0" iyy="0.0015" iyz="0" izz="0.00593333333333"/>
    </inertial>
    <visual>
      <origin rpy="0 0 0" xyz="0 0 0"/>
      <geometry>
        <mesh filename="package://darias_description/meshes/arm/convex/arm_segment_a_convex.stl"/>
      </geometry>
      <material name="Blue"/>
    </visual>
    <collision>
      <origin rpy="0 0 0" xyz="0 0 0"/>
      <geometry>
        <mesh filename="package://darias_description/meshes/arm/convex/arm_segment_a_convex.stl"/>
      </geometry>
    </collision>
  </link>
  <gazebo reference="R_3_link">
    <material value="Gazebo/Blue"/>
    <turnGravityOff>1</turnGravityOff>
  </gazebo>
  <transmission name="R_2_trans">
    <type>transmission_interface/SimpleTransmission</type>
    <joint name="R_HR">
      <hardwareInterface>EffortJointInterface</hardwareInterface>
    </joint>
    <actuator name="R_2_motor">
      
      <mechanicalReduction>1</mechanicalReduction>
    </actuator>
  </transmission>
  <joint name="R_EB" type="revolute">
    <origin rpy="0 0 0" xyz="0 0 0.20"/>
    <axis xyz="0 1 0"/>
    <limit effort="10000.0" lower="-2.094395" upper="2.094395" velocity="2.26892802759"/>
    <!-- 306 -->
    <safety_controller k_position="100" k_velocity="2" soft_lower_limit="-2.05948851735" soft_upper_limit="2.05948851735"/>
    <dynamics damping="0.1"/>
    <parent link="R_3_link"/>
    <child link="R_4_link"/>
  </joint>
  <link name="R_4_link">
    <inertial>
      <mass value="1.0"/>
      <origin rpy="0 0 0" xyz="0 -0.06 0.07"/>
      <inertia ixx="0.00683333333333" ixy="0" ixz="0" iyy="0.0015" iyz="0" izz="0.00593333333333"/>
    </inertial>
    <visual>
      <origin rpy="0 3.14159265359 3.14159265359" xyz="0 0 0.2"/>
      <geometry>
        <mesh filename="package://darias_description/meshes/arm/convex/arm_segment_b_convex.stl"/>
      </geometry>
      <material name="Blue"/>
    </visual>
    <collision>
      <origin rpy="0 3.14159265359 3.14159265359" xyz="0 0 0.2"/>
      <geometry>
        <mesh filename="package://darias_description/meshes/arm/convex/arm_segment_b_convex.stl"/>
      </geometry>
    </collision>
  </link>
  <gazebo reference="R_4_link">
    <material value="Gazebo/Blue"/>
    <turnGravityOff>1</turnGravityOff>
  </gazebo>
  <transmission name="R_3_trans">
    <type>transmission_interface/SimpleTransmission</type>
    <joint name="R_EB">
      <hardwareInterface>EffortJointInterface</hardwareInterface>
    </joint>
    <actuator name="R_3_motor">
     
      <mechanicalReduction>1</mechanicalReduction>
    </actuator>
  </transmission>
  <joint name="R_WR" type="revolute">
    <origin rpy="0 0 0" xyz="0 0 0.20"/>
    <axis xyz="0 0 1"/>
    <limit effort="10000.0" lower="-2.967059" upper="2.967059" velocity="2.26892802759"/>
    <!-- 204 -->
    <safety_controller k_position="100" k_velocity="2" soft_lower_limit="-2.93215314335" soft_upper_limit="2.93215314335"/>
    <dynamics damping="0.1"/>
    <parent link="R_4_link"/>
    <child link="R_5_link"/>
  </joint>
  <link name="R_5_link">
    <inertial>
      <mass value="1.0"/>
      <origin rpy="0 0 0" xyz="0 0 0.124"/>
      <inertia ixx="0.00632533333333" ixy="0" ixz="0" iyy="0.0015" iyz="0" izz="0.00542533333333"/>
    </inertial>
    <visual>
      <origin rpy="0 0 3.14159265359" xyz="0 0 0"/>
      <geometry name="R_5_geom">
        <mesh filename="package://darias_description/meshes/arm/convex/arm_segment_last_convex.stl"/>
      </geometry>
      <material name="Blue"/>
    </visual>
    <collision>
      <origin rpy="0 0 3.14159265359" xyz="0 0 0"/>
      <geometry>
        <mesh filename="package://darias_description/meshes/arm/convex/arm_segment_last_convex.stl"/>
      </geometry>
    </collision>
  </link>
  <gazebo reference="R_5_link">
    <material value="Gazebo/Blue"/>
    <turnGravityOff>1</turnGravityOff>
  </gazebo>
  <transmission name="R_4_trans">
    <type>transmission_interface/SimpleTransmission</type>
    <joint name="R_WR">
      <hardwareInterface>EffortJointInterface</hardwareInterface>
    </joint>
    <actuator name="R_4_motor">
      <mechanicalReduction>1</mechanicalReduction>
    </actuator>
  </transmission>
  <joint name="R_WFE" type="revolute">
    <origin rpy="0 0 0" xyz="0 0 0.19"/>
    <axis xyz="0 -1 0"/>
    <limit effort="10000.0" lower="-2.094395" upper="2.094395" velocity="3.14159265359"/>
    <!-- 306 -->
    <safety_controller k_position="100" k_velocity="2" soft_lower_limit="-2.05948851735" soft_upper_limit="2.05948851735"/>
    <dynamics damping="0.1"/>
    <parent link="R_5_link"/>
    <child link="R_6_link"/>
  </joint>
  <link name="R_6_link">
    <inertial>
      <mass value="1.0"/>
      <origin rpy="0 0 0" xyz="0 0 0.0625"/>
      <inertia ixx="0.00260416666667" ixy="0" ixz="0" iyy="0.00260416666667" iyz="0" izz="0.00260416666667"/>
    </inertial>
    <visual>
      <origin rpy="0 0 3.14159265359" xyz="0 0 0"/>
      <geometry>
        <mesh filename="package://darias_description/meshes/arm/convex/arm_wrist_convex.stl"/>
      </geometry>
      <material name="HandGray"/>
    </visual>
    <collision>
      <origin rpy="0 0 3.14159265359" xyz="0 0 0"/>
      <geometry>
        <mesh filename="package://darias_description/meshes/arm/convex/arm_wrist_convex.stl"/>
      </geometry>
    </collision>
  </link>
  <gazebo reference="R_6_link">
    <material value="Gazebo/White"/>
    <turnGravityOff>1</turnGravityOff>
  </gazebo>
  <transmission name="R_5_trans" >
    <type>transmission_interface/SimpleTransmission</type>
    <joint name="R_WFE">
      <hardwareInterface>EffortJointInterface</hardwareInterface>
    </joint>
    <actuator name="R_5_motor">
      <mechanicalReduction>1</mechanicalReduction>
    </actuator>
  </transmission>
  <joint name="R_WAA" type="revolute">
    <origin rpy="0 0 0" xyz="0.0 0 0.078"/>
    <axis xyz="0 0 1"/>
    <limit effort="10000.0" lower="-2.967059" upper="2.967059" velocity="3.14159265359"/>
    <safety_controller k_position="100" k_velocity="2" soft_lower_limit="-2.93215314335" soft_upper_limit="2.93215314335"/>
    <dynamics damping="0.1"/>
    <parent link="R_6_link"/>
    <child link="right_endeffector_link"/>
  </joint>
  <transmission name="R_6_trans">
    <type>transmission_interface/SimpleTransmission</type>
    <joint name="R_WAA">
      <hardwareInterface>EffortJointInterface</hardwareInterface>
    </joint>
    <actuator name="R_6_motor">
      <mechanicalReduction>1</mechanicalReduction>
    </actuator>
  </transmission>
  <link name="right_endeffector_link">
    <inertial>
      <mass value="1"/>
      <origin rpy="0 0 0" xyz="0 0 0.0625"/>
      <inertia ixx="0.00260416666667" ixy="0" ixz="0" iyy="0.00260416666667" iyz="0" izz="0.00260416666667"/>
    </inertial>
  </link>
  <gazebo reference="right_endeffector_link">
    <material value="Gazebo/White"/>
    <turnGravityOff>1</turnGravityOff>
  </gazebo>
  <!-- Darias left arm -->
  <joint name="darias_L_base" type="fixed">
    <origin rpy="1.570796 1.570796 2.617993878" xyz="-0.11 0.06 0.193"/>
    <parent link="darias"/>
    <child link="calib_L_base_link"/>
  </joint>
  <link name="calib_L_base_link">
    <inertial>
      <mass value="1.0"/>
      <origin rpy="0 0 0" xyz="0 0 0.055"/>
      <inertia ixx="0.00190833333333" ixy="0" ixz="0" iyy="0.0018" iyz="0" izz="0.00190833333333"/>
    </inertial>
    <visual>
      <origin rpy="0 0 0" xyz="0 0 0"/>
      <geometry>
        <mesh filename="package://darias_description/meshes/arm/convex/arm_base_convex.stl"/>
      </geometry>
      <material name="Blue"/>
    </visual>
    <collision>
      <origin rpy="0 0 0" xyz="0 0 0"/>
      <geometry>
        <mesh filename="package://darias_description/meshes/arm/convex/arm_base_convex.stl"/>
      </geometry>
    </collision>
  </link>
  <gazebo reference="calib_L_base_link">
    <material value="Gazebo/Blue"/>
    <turnGravityOff>1</turnGravityOff>
  </gazebo>
  <joint name="L_SFE" type="revolute">
    <!-- former revolute -->
    <origin rpy="0 0 0" xyz="0 0 0.11"/>
    <axis xyz="0 0 1"/>
    <limit effort="10000.0" lower="-2.967059" upper="2.967059" velocity="1.91986217719"/>
    <!-- 204 -->
    <safety_controller k_position="100" k_velocity="2" soft_lower_limit="-2.93215314335" soft_upper_limit="2.93215314335"/>
    <dynamics damping="0.1"/>
    <parent link="calib_L_base_link"/>
    <child link="L_1_link"/>
  </joint>
  <link name="L_1_link">
    <inertial>
      <mass value="1.0"/>
      <origin rpy="0 0 0" xyz="0 0 0.130"/>
      <inertia ixx="0.00683333333333" ixy="0" ixz="0" iyy="0.0015" iyz="0" izz="0.00593333333333"/>
    </inertial>
    <visual>
      <origin rpy="0 0 3.14159265359" xyz="0 0 0"/>
      <geometry>
        <mesh filename="package://darias_description/meshes/arm/convex/arm_segment_a_convex.stl"/>
      </geometry>
      <material name="Blue"/>
    </visual>
    <collision>
      <origin rpy="0 0 3.14159265359" xyz="0 0 0"/>
      <geometry>
        <mesh filename="package://darias_description/meshes/arm/convex/arm_segment_a_convex.stl"/>
      </geometry>
    </collision>
  </link>
  <gazebo reference="L_1_link">
    <material value="Gazebo/Blue"/>
    <turnGravityOff>1</turnGravityOff>
  </gazebo>
  <transmission name="L_0_trans">
    <type>transmission_interface/SimpleTransmission</type>
    <joint name="L_SFE">
      <hardwareInterface>EffortJointInterface</hardwareInterface>
    </joint>
    <actuator name="L_0_motor">
      <mechanicalReduction>1</mechanicalReduction>
    </actuator>
  </transmission>
  <joint name="L_SAA" type="revolute">
    <origin rpy="0 0 0" xyz="0 0 0.20"/>
    <axis xyz="0 -1 0"/>
    <limit effort="10000.0" lower="-2.094395" upper="2.094395" velocity="1.91986217719"/>
    <!-- effort 306 -->
    <safety_controller k_position="100" k_velocity="2" soft_lower_limit="-2.05948851735" soft_upper_limit="2.05948851735"/>
    <dynamics damping="0.1"/>
    <parent link="L_1_link"/>
    <child link="L_2_link"/>
  </joint>
  <link name="L_2_link">
    <inertial>
      <mass value="1.0"/>
      <origin rpy="0 0 0" xyz="0 0.06 0.07"/>
      <inertia ixx="0.00683333333333" ixy="0" ixz="0" iyy="0.0015" iyz="0" izz="0.00593333333333"/>
    </inertial>
    <visual>
      <origin rpy="3.14159265359 0 3.14159265359" xyz="0 0 0.2"/>
      <geometry>
        <mesh filename="package://darias_description/meshes/arm/convex/arm_segment_b_convex.stl"/>
      </geometry>
      <material name="Blue"/>
    </visual>
    <collision>
      <origin rpy="3.14159265359 0 3.14159265359" xyz="0 0 0.2"/>
      <geometry>
        <mesh filename="package://darias_description/meshes/arm/convex/arm_segment_b_convex.stl"/>
      </geometry>
    </collision>
  </link>
  <gazebo reference="L_2_link">
    <material value="Gazebo/Blue"/>
    <turnGravityOff>1</turnGravityOff>
  </gazebo>
  <transmission name="L_1_trans">
    <type>transmission_interface/SimpleTransmission</type>
    <joint name="L_SAA">
      <hardwareInterface>EffortJointInterface</hardwareInterface>
    </joint>
    <actuator name="L_1_motor">
      <mechanicalReduction>1</mechanicalReduction>
    </actuator>
  </transmission>
  <joint name="L_HR" type="revolute">
    <origin rpy="0 0 0" xyz="0 0 0.20"/>
    <axis xyz="0 0 1"/>
    <limit effort="10000.0" lower="-2.967059" upper="2.967059" velocity="2.26892802759"/>
    <!-- 204 -->
    <safety_controller k_position="100" k_velocity="2" soft_lower_limit="-2.93215314335" soft_upper_limit="2.93215314335"/>
    <dynamics damping="0.1"/>
    <parent link="L_2_link"/>
    <child link="L_3_link"/>
  </joint>
  <link name="L_3_link">
    <inertial>
      <mass value="1.0"/>
      <origin rpy="0 0 0" xyz="0 0.06 0.130"/>
      <inertia ixx="0.00683333333333" ixy="0" ixz="0" iyy="0.0015" iyz="0" izz="0.00593333333333"/>
    </inertial>
    <visual>
      <origin rpy="0 0 0" xyz="0 0 0"/>
      <geometry>
        <mesh filename="package://darias_description/meshes/arm/convex/arm_segment_a_convex.stl"/>
      </geometry>
      <material name="Blue"/>
    </visual>
    <collision>
      <origin rpy="0 0 0" xyz="0 0 0"/>
      <geometry>
        <mesh filename="package://darias_description/meshes/arm/convex/arm_segment_a_convex.stl"/>
      </geometry>
    </collision>
  </link>
  <gazebo reference="L_3_link">
    <material value="Gazebo/Blue"/>
    <turnGravityOff>1</turnGravityOff>
  </gazebo>
  <transmission name="L_2_trans">
    <type>transmission_interface/SimpleTransmission</type>
    <joint name="L_HR">
      <hardwareInterface>EffortJointInterface</hardwareInterface>
    </joint>
    <actuator name="L_2_motor">
      <mechanicalReduction>1</mechanicalReduction>
    </actuator>
  </transmission>
  <joint name="L_EB" type="revolute">
    <origin rpy="0 0 0" xyz="0 0 0.20"/>
    <axis xyz="0 1 0"/>
    <limit effort="10000.0" lower="-2.094395" upper="2.094395" velocity="2.26892802759"/>
    <!-- 306 -->
    <safety_controller k_position="100" k_velocity="2" soft_lower_limit="-2.05948851735" soft_upper_limit="2.05948851735"/>
    <dynamics damping="0.1"/>
    <parent link="L_3_link"/>
    <child link="L_4_link"/>
  </joint>
  <link name="L_4_link">
    <inertial>
      <mass value="1.0"/>
      <origin rpy="0 0 0" xyz="0 -0.06 0.07"/>
      <inertia ixx="0.00683333333333" ixy="0" ixz="0" iyy="0.0015" iyz="0" izz="0.00593333333333"/>
    </inertial>
    <visual>
      <origin rpy="0 3.14159265359 3.14159265359" xyz="0 0 0.2"/>
      <geometry>
        <mesh filename="package://darias_description/meshes/arm/convex/arm_segment_b_convex.stl"/>
      </geometry>
      <material name="Blue"/>
    </visual>
    <collision>
      <origin rpy="0 3.14159265359 3.14159265359" xyz="0 0 0.2"/>
      <geometry>
        <mesh filename="package://darias_description/meshes/arm/convex/arm_segment_b_convex.stl"/>
      </geometry>
    </collision>
  </link>
  <gazebo reference="L_4_link">
    <material value="Gazebo/Blue"/>
    <turnGravityOff>1</turnGravityOff>
  </gazebo>
  <transmission name="L_3_trans">
    <type>transmission_interface/SimpleTransmission</type>
    <joint name="L_EB">
      <hardwareInterface>EffortJointInterface</hardwareInterface>
    </joint>
    <actuator name="L_3_motor">
      <mechanicalReduction>1</mechanicalReduction>
    </actuator>
  </transmission>
  <joint name="L_WR" type="revolute">
    <origin rpy="0 0 0" xyz="0 0 0.20"/>
    <axis xyz="0 0 1"/>
    <limit effort="10000.0" lower="-2.967059" upper="2.967059" velocity="2.26892802759"/>
    <!-- 204 -->
    <safety_controller k_position="100" k_velocity="2" soft_lower_limit="-2.93215314335" soft_upper_limit="2.93215314335"/>
    <dynamics damping="0.1"/>
    <parent link="L_4_link"/>
    <child link="L_5_link"/>
  </joint>
  <link name="L_5_link">
    <inertial>
      <mass value="1.0"/>
      <origin rpy="0 0 0" xyz="0 0 0.124"/>
      <inertia ixx="0.00632533333333" ixy="0" ixz="0" iyy="0.0015" iyz="0" izz="0.00542533333333"/>
    </inertial>
    <visual>
      <origin rpy="0 0 3.14159265359" xyz="0 0 0"/>
      <geometry name="L_5_geom">
        <mesh filename="package://darias_description/meshes/arm/convex/arm_segment_last_convex.stl"/>
      </geometry>
      <material name="Blue"/>
    </visual>
    <collision>
      <origin rpy="0 0 3.14159265359" xyz="0 0 0"/>
      <geometry>
        <mesh filename="package://darias_description/meshes/arm/convex/arm_segment_last_convex.stl"/>
      </geometry>
    </collision>
  </link>
  <gazebo reference="L_5_link">
    <material value="Gazebo/Blue"/>
    <turnGravityOff>1</turnGravityOff>
  </gazebo>
  <transmission name="L_4_trans">
    <type>transmission_interface/SimpleTransmission</type>
    <joint name="L_WR">
      <hardwareInterface>EffortJointInterface</hardwareInterface>
    </joint>
    <actuator name="L_4_motor">
      <mechanicalReduction>1</mechanicalReduction>
    </actuator>
  </transmission>
  <joint name="L_WFE" type="revolute">
    <origin rpy="0 0 0" xyz="0 0 0.19"/>
    <axis xyz="0 -1 0"/>
    <limit effort="10000.0" lower="-2.094395" upper="2.094395" velocity="3.14159265359"/>
    <!-- 306 -->
    <safety_controller k_position="100" k_velocity="2" soft_lower_limit="-2.05948851735" soft_upper_limit="2.05948851735"/>
    <dynamics damping="0.1"/>
    <parent link="L_5_link"/>
    <child link="L_6_link"/>
  </joint>
  <link name="L_6_link">
    <inertial>
      <mass value="1.0"/>
      <origin rpy="0 0 0" xyz="0 0 0.0625"/>
      <inertia ixx="0.00260416666667" ixy="0" ixz="0" iyy="0.00260416666667" iyz="0" izz="0.00260416666667"/>
    </inertial>
    <visual>
      <origin rpy="0 0 3.14159265359" xyz="0 0 0"/>
      <geometry>
        <mesh filename="package://darias_description/meshes/arm/convex/arm_wrist_convex.stl"/>
      </geometry>
      <material name="HandGray"/>
    </visual>
    <collision>
      <origin rpy="0 0 3.14159265359" xyz="0 0 0"/>
      <geometry>
        <mesh filename="package://darias_description/meshes/arm/convex/arm_wrist_convex.stl"/>
      </geometry>
    </collision>
  </link>
  <gazebo reference="L_6_link">
    <material value="Gazebo/White"/>
    <turnGravityOff>1</turnGravityOff>
  </gazebo>
  <transmission name="L_5_trans">
    <type>transmission_interface/SimpleTransmission</type>
    <joint name="L_WFE">
      <hardwareInterface>EffortJointInterface</hardwareInterface>
    </joint>
    <actuator name="L_5_motor">
      <mechanicalReduction>1</mechanicalReduction>
    </actuator>
  </transmission>
  <joint name="L_WAA" type="revolute">
    <origin rpy="0 0 0" xyz="0.0 0 0.078"/>
    <axis xyz="0 0 1"/>
    <limit effort="10000.0" lower="-2.094395" upper="2.094395" velocity="3.14159265359"/>
    <safety_controller k_position="100" k_velocity="2" soft_lower_limit="-2.93215314335" soft_upper_limit="2.93215314335"/>
    <dynamics damping="0.1"/>
    <parent link="L_6_link"/>
    <child link="left_endeffector_link"/>
  </joint>
  <transmission name="L_6_trans">
    <type>transmission_interface/SimpleTransmission</type>
    <joint name="L_WAA">
      <hardwareInterface>EffortJointInterface</hardwareInterface>
    </joint>
    <actuator name="L_6_motor">
      <mechanicalReduction>1</mechanicalReduction>
    </actuator>
  </transmission>
  <link name="left_endeffector_link">
    <inertial>
      <mass value="1"/>
      <origin rpy="0 0 0" xyz="0 0 0.0625"/>
      <inertia ixx="0.00260416666667" ixy="0" ixz="0" iyy="0.00260416666667" iyz="0" izz="0.00260416666667"/>
    </inertial>
  </link>
  <gazebo reference="left_endeffector_link">
    <material value="Gazebo/White"/>
    <turnGravityOff>1</turnGravityOff>
  </gazebo>
  <!-- right Hand of darias -->
  
  <!-- left Hand of darias -->
 
  
  <!-- gazebo plugin for ros control -->
  <gazebo>
    <plugin filename="libgazebo_ros_control.so" name="gazebo_ros_control">
      <robotNamespace>/darias</robotNamespace>
    </plugin>
  </gazebo>
</robot>
