<?xml version="1.0"?>
<robot name="3_link_planar">
  <link name="world"/>

  <joint name="F_base_joint" type="fixed">
    <origin rpy="0.0 0.0 0.0" xyz="0.0 0.0 0.0"/>
    <parent link="world"/>
    <child link="F_base_link"/>
  </joint>

  <link name="F_base_link">
    <inertial>
      <origin rpy="0 0 0" xyz="0.0 0.0 0.0"/>
      <mass value="1"/>
      <inertia ixx="0.05" ixy="0" ixz="0" iyy="0.018" iyz="0" izz="0.044"/>
    </inertial>
    <visual>
      <geometry>
        <cylinder radius="0.075" length="0.4"/>
      </geometry>
      <material name="black">
        <color rgba="0 0 0 1"/>
      </material>
    </visual>
    <collision>
      <geometry>
        <cylinder radius="0.075" length="0.4"/>
      </geometry>
    </collision>
  </link>

  <joint name="F_joint_1" type="revolute">
    <axis xyz="0 0 1"/>
    <parent link="F_base_link"/>
    <child link="F_link_1"/>
    <origin xyz="0.0 0.0 0.0" rpy="0.0 0.0 0.0"/>
    <limit effort="320.0" lower="-2.9670597283903604" upper="2.9670597283903604" velocity="2.35619449019"/>
  </joint>

  <link name="F_link_1">
    <inertial>
      <origin rpy="0 0 0" xyz="0.21 0.0 0.0"/>
      <mass value="1"/>
      <inertia ixx="0.0008" ixy="0" ixz="0" iyy="0.0151" iyz="0" izz="0.0151"/>
    </inertial>
    <visual>
      <geometry>
        <cylinder radius="0.04" length="0.42"/>
      </geometry>
      <origin rpy="0 1.57079632679 0" xyz="0.21 0.0 0.0"/>
      <material name="red">
        <color rgba="0.8 0 0 1"/>
      </material>
    </visual>
    <collision>
      <geometry>
        <cylinder radius="0.04" length="0.42"/>
      </geometry>
       <origin rpy="0 1.57079632679 0" xyz="0.21 0.0 0.0"/>
    </collision>
  </link>

  <joint name="F_joint_2" type="revolute">
    <axis xyz="0 0 1"/>
    <parent link="F_link_1"/>
    <child link="F_link_2"/>
    <origin xyz="0.42 0 0"/>
    <limit effort="176.0" lower="-2.0943951023931953" upper="2.0943951023931953" velocity="2.35619449019"/>
  </joint>

  <link name="F_link_2">
    <inertial>
      <origin rpy="0 0 0" xyz="0.21 0.0 0.0"/>
      <mass value="1"/>
      <inertia ixx="0.0008" ixy="0" ixz="0" iyy="0.0137" iyz="0" izz="0.0137"/>
    </inertial>
    <visual>
      <geometry>
        <cylinder radius="0.04" length="0.4"/>
      </geometry>
      <origin rpy="0.0 1.57079632679 0" xyz="0.2 0.0 0.0"/>
      <material name="green">
        <color rgba="0 0.8 0.0 1"/>
      </material>
    </visual>
    <collision>
      <geometry>
        <cylinder radius="0.04" length="0.4"/>
      </geometry>
       <origin rpy="0 1.57079632679 0" xyz="0.2 0.0 0.0"/>
    </collision>
  </link>

  <joint name="F_joint_3" type="revolute">
    <axis xyz="0 0 1"/>
    <parent link="F_link_2"/>
    <child link="F_link_3"/>
    <origin xyz="0.4 0 0"/>
    <limit effort="40.0" lower="-2.0943951023931953" upper="2.0943951023931953" velocity="2.35619449019"/>
  </joint>

  <link name="F_link_3">
    <inertial>
      <origin rpy="0 0 0" xyz="0.21 0.0 0.0"/>
      <mass value="1"/>
      <inertia ixx="0.0008" ixy="0" ixz="0" iyy="0.0023" iyz="0" izz="0.0023"/>
    </inertial>
    <visual>
      <geometry>
        <cylinder radius="0.04" length="0.151"/>
      </geometry>
      <origin rpy="0 1.57079632679 0" xyz="0.0755 0 0"/>
      <material name="blue">
        <color rgba="0 0 .8 1"/>
      </material>
    </visual>
    <collision>
      <geometry>
        <cylinder radius="0.04" length="0.151"/>
      </geometry>
      <origin rpy="0 1.57079632679 0" xyz="0.0755 0.0 0.0"/>
    </collision>
  </link>

  <joint name="F_joint_striker" type="fixed">
      <axis xyz="1 0 0"/>
      <parent link="F_link_3"/>
      <child link="F_link_striker_hand"/>
      <origin xyz="0.151 0 0.0"/>
  </joint>

  <link name="F_link_striker_hand">
    <inertial>
      <origin rpy="0 0 0" xyz="0.0 0.0 0.0"/>
      <mass value="0.1"/>
      <inertia ixx="0.0008" ixy="0" ixz="0" iyy="0.0023" iyz="0" izz="0.0023"/>
    </inertial>
    <visual>
      <geometry>
        <cylinder radius="0.01" length="0.189"/>
      </geometry>
      <origin rpy="0 0 0" xyz="0.0 0 -0.0945"/>
      <material name="grey">
        <color rgba="0.8 0.8 .8 1"/>
      </material>
    </visual>
    <collision>
      <geometry>
        <cylinder radius="0.01" length="0.189"/>
      </geometry>
      <origin rpy="0 0 0" xyz="0.0 0 -0.0945"/>
      <surface>
        <bounce>
          <restitution_coefficient>0.8</restitution_coefficient>
        </bounce>
        <contact>
          <ode>
            <soft_cfm>0.1</soft_cfm>
            <soft_erp>0.1</soft_erp>
            <max_vel>1</max_vel>
          </ode>
        </contact>
      </surface>
    </collision>
    <contact>
      <restitution value="1.0"/>
      <lateral_friction value="1.0"/>
      <rolling_friction value="0.0"/>
      <spinning_friction value="0.0"/>
    </contact>
  </link>

  <joint name="F_joint_striker_ee" type="fixed">
      <axis xyz="1 0 0"/>
      <parent link="F_link_striker_hand"/>
      <child link="F_link_striker_ee"/>
      <origin xyz="0.0 0 -0.189"/>
  </joint>

  <link name="F_link_striker_ee">
    <inertial>
      <origin rpy="0 0 0" xyz="0.0 0.0 0.01"/>
      <mass value="0.1"/>
      <inertia ixx="0.0008" ixy="0" ixz="0" iyy="0.0023" iyz="0" izz="0.0023"/>
    </inertial>
    <visual>
      <geometry>
        <cylinder radius="0.05" length="0.02"/>
      </geometry>
      <origin rpy="0 0 0" xyz="0.0 0 0.01"/>
      <material name="grey">
        <color rgba="0.8 0.8 .8 1"/>
      </material>
    </visual>
    <collision>
      <geometry>
        <cylinder radius="0.05" length="0.1"/>
      </geometry>
      <origin rpy="0 0 0" xyz="0.0 0.0 0.01"/>
      <surface>
        <bounce>
          <restitution_coefficient>0.8</restitution_coefficient>
        </bounce>
        <contact>
          <ode>
            <soft_cfm>0.1</soft_cfm>
            <soft_erp>0.1</soft_erp>
            <max_vel>1</max_vel>
          </ode>
        </contact>
      </surface>
    </collision>
    <contact>
      <restitution value="1.0"/>
      <lateral_friction value="1.0"/>
      <rolling_friction value="0.0"/>
      <spinning_friction value="0.0"/>
    </contact>
  </link>

  <joint name="B_base_joint" type="fixed">
    <origin rpy="0.0 0.0 3.14159265359" xyz="3.02 0.0 0.0"/>
    <parent link="world"/>
    <child link="B_base_link"/>
  </joint>

  <link name="B_base_link">
    <inertial>
      <origin rpy="0 0 0" xyz="0.0 0.0 0.0"/>
      <mass value="1"/>
      <inertia ixx="0.05" ixy="0" ixz="0" iyy="0.018" iyz="0" izz="0.044"/>
    </inertial>
    <visual>
      <geometry>
        <cylinder radius="0.075" length="0.4"/>
      </geometry>
      <material name="black">
        <color rgba="0 0 0 1"/>
      </material>
    </visual>
    <collision>
      <geometry>
        <cylinder radius="0.075" length="0.4"/>
      </geometry>
    </collision>
  </link>

  <joint name="B_joint_1" type="revolute">
    <axis xyz="0 0 1"/>
    <parent link="B_base_link"/>
    <child link="B_link_1"/>
    <origin xyz="0.0 0.0 0.0" rpy="0.0 0.0 0.0"/>
    <limit effort="320.0" lower="-2.9670597283903604" upper="2.9670597283903604" velocity="2.35619449019"/>
  </joint>

  <link name="B_link_1">
    <inertial>
      <origin rpy="0 0 0" xyz="0.21 0.0 0.0"/>
      <mass value="1"/>
      <inertia ixx="0.0008" ixy="0" ixz="0" iyy="0.0151" iyz="0" izz="0.0151"/>
    </inertial>
    <visual>
      <geometry>
        <cylinder radius="0.04" length="0.42"/>
      </geometry>
      <origin rpy="0 1.57079632679 0" xyz="0.21 0.0 0.0"/>
      <material name="red">
        <color rgba="0.8 0 0 1"/>
      </material>
    </visual>
    <collision>
      <geometry>
        <cylinder radius="0.04" length="0.42"/>
      </geometry>
       <origin rpy="0 1.57079632679 0" xyz="0.21 0.0 0.0"/>
    </collision>
  </link>

  <joint name="B_joint_2" type="revolute">
    <axis xyz="0 0 1"/>
    <parent link="B_link_1"/>
    <child link="B_link_2"/>
    <origin xyz="0.42 0 0"/>
    <limit effort="176.0" lower="-2.0943951023931953" upper="2.0943951023931953" velocity="2.35619449019"/>
  </joint>

  <link name="B_link_2">
    <inertial>
      <origin rpy="0 0 0" xyz="0.21 0.0 0.0"/>
      <mass value="1"/>
      <inertia ixx="0.0008" ixy="0" ixz="0" iyy="0.0137" iyz="0" izz="0.0137"/>
    </inertial>
    <visual>
      <geometry>
        <cylinder radius="0.04" length="0.4"/>
      </geometry>
      <origin rpy="0.0 1.57079632679 0" xyz="0.2 0.0 0.0"/>
      <material name="green">
        <color rgba="0 0.8 0.0 1"/>
      </material>
    </visual>
    <collision>
      <geometry>
        <cylinder radius="0.04" length="0.4"/>
      </geometry>
       <origin rpy="0 1.57079632679 0" xyz="0.2 0.0 0.0"/>
    </collision>
  </link>

  <joint name="B_joint_3" type="revolute">
    <axis xyz="0 0 1"/>
    <parent link="B_link_2"/>
    <child link="B_link_3"/>
    <origin xyz="0.4 0 0"/>
    <limit effort="40.0" lower="-2.0943951023931953" upper="2.0943951023931953" velocity="2.35619449019"/>
  </joint>

  <link name="B_link_3">
    <inertial>
      <origin rpy="0 0 0" xyz="0.21 0.0 0.0"/>
      <mass value="1"/>
      <inertia ixx="0.0008" ixy="0" ixz="0" iyy="0.0023" iyz="0" izz="0.0023"/>
    </inertial>
    <visual>
      <geometry>
        <cylinder radius="0.04" length="0.151"/>
      </geometry>
      <origin rpy="0 1.57079632679 0" xyz="0.0755 0 0"/>
      <material name="blue">
        <color rgba="0 0 .8 1"/>
      </material>
    </visual>
    <collision>
      <geometry>
        <cylinder radius="0.04" length="0.151"/>
      </geometry>
      <origin rpy="0 1.57079632679 0" xyz="0.0755 0.0 0.0"/>
    </collision>
  </link>

  <joint name="B_joint_striker" type="fixed">
      <axis xyz="1 0 0"/>
      <parent link="B_link_3"/>
      <child link="B_link_striker_hand"/>
      <origin xyz="0.151 0 0.0"/>
  </joint>

  <link name="B_link_striker_hand">
    <inertial>
      <origin rpy="0 0 0" xyz="0.0 0.0 0.0"/>
      <mass value="0.1"/>
      <inertia ixx="0.0008" ixy="0" ixz="0" iyy="0.0023" iyz="0" izz="0.0023"/>
    </inertial>
    <visual>
      <geometry>
        <cylinder radius="0.01" length="0.189"/>
      </geometry>
      <origin rpy="0 0 0" xyz="0.0 0 -0.0945"/>
      <material name="grey">
        <color rgba="0.8 0.8 .8 1"/>
      </material>
    </visual>
    <collision>
      <geometry>
        <cylinder radius="0.01" length="0.189"/>
      </geometry>
      <origin rpy="0 0 0" xyz="0.0 0 -0.0945"/>
      <surface>
        <bounce>
          <restitution_coefficient>0.8</restitution_coefficient>
        </bounce>
        <contact>
          <ode>
            <soft_cfm>0.1</soft_cfm>
            <soft_erp>0.1</soft_erp>
            <max_vel>1</max_vel>
          </ode>
        </contact>
      </surface>
    </collision>
  </link>

  <joint name="B_joint_striker_ee" type="fixed">
      <axis xyz="1 0 0"/>
      <parent link="B_link_striker_hand"/>
      <child link="B_link_striker_ee"/>
      <origin xyz="0.0 0 -0.189"/>
  </joint>

  <link name="B_link_striker_ee">
    <inertial>
      <origin rpy="0 0 0" xyz="0.0 0.0 0.01"/>
      <mass value="0.1"/>
      <inertia ixx="0.0008" ixy="0" ixz="0" iyy="0.0023" iyz="0" izz="0.0023"/>
    </inertial>
    <visual>
      <geometry>
        <cylinder radius="0.05" length="0.02"/>
      </geometry>
      <origin rpy="0 0 0" xyz="0.0 0 0.01"/>
      <material name="grey">
        <color rgba="0.8 0.8 .8 1"/>
      </material>
    </visual>
    <collision>
      <geometry>
        <cylinder radius="0.05" length="0.1"/>
      </geometry>
      <origin rpy="0 0 0" xyz="0.0 0.0 0.01"/>
      <surface>
        <bounce>
          <restitution_coefficient>0.8</restitution_coefficient>
        </bounce>
        <contact>
          <ode>
            <soft_cfm>0.1</soft_cfm>
            <soft_erp>0.1</soft_erp>
            <max_vel>1</max_vel>
          </ode>
        </contact>
      </surface>
    </collision>
  </link>
</robot>