<?xml version="1.0"?>
<robot name="4_link_planar">
   <material name="Blue_pastel">
    <color rgba="0.482 0.8 0.894 1."/>
  </material>

  <material name="Blue_pastel2">
    <color rgba="0.582 0.9 0.994 1."/>
  </material>
  <material name="white_clean">
    <color rgba="0.98 0.901 0.71 1."/>
  </material>
  <link name="world"/>

  <joint name="base_joint" type="fixed">
    <origin rpy="0.0 0.0 0.0" xyz="0.0 0.0 0.0"/>
    <parent link="world"/>
    <child link="base_link"/>
  </joint>

  <link name="base_link">
    <inertial>
      <origin rpy="0 0 0" xyz="0.0 0.0 0.0"/>
      <mass value="1"/>
      <inertia ixx="0.05" ixy="0" ixz="0" iyy="0.018" iyz="0" izz="0.044"/>
    </inertial>
    <visual>
      <geometry>
        <sphere radius="0.1"/>
      </geometry>
      <material name="white_clean"/>
    </visual>
    <collision>
      <geometry>
        <sphere radius="0.1"/>
      </geometry>
    </collision>
  </link>

  <joint name="joint_1" type="revolute">
    <axis xyz="0 0 1"/>
    <parent link="base_link"/>
    <child link="link_1"/>
    <origin xyz="0.0 0.0 0.0" rpy="0.0 0.0 0.0"/>
    <limit effort="320.0" lower="-2.9670597283903604" upper="2.9670597283903604" velocity="2.35619449019"/>
  </joint>

  <link name="link_1">
    <inertial>
      <origin rpy="0 0 0" xyz="0.3 0.0 0.0"/>
      <mass value="1"/>
      <inertia ixx="0.0008" ixy="0" ixz="0" iyy="0.0151" iyz="0" izz="0.0151"/>
    </inertial>
    <visual>
      <origin rpy="0 1.57079632679 0" xyz="0.3 0.0 0.0"/>
      <geometry>
        <cylinder radius="0.03" length="0.39"/>
      </geometry>
      <material name="Blue_pastel"/>
    </visual>
    <collision>
      <origin rpy="0 1.57079632679 0" xyz="0.3 0.0 0.0"/>
      <geometry>
        <cylinder radius="0.03" length="0.39"/>
      </geometry>
    </collision>
  </link>

  <joint name="fix_joint_1" type="fixed">
    <axis xyz="0 0 1"/>
    <parent link="link_1"/>
    <child link="ball_1"/>
    <origin xyz="0.54 0.0 0.0" rpy="0.0 0.0 0.0"/>
  </joint>

  <link name="ball_1">
    <inertial>
      <origin rpy="0 0 0" xyz="0.0 0.0 0.0"/>
      <mass value="1"/>
      <inertia ixx="0.0008" ixy="0" ixz="0" iyy="0.0151" iyz="0" izz="0.0151"/>
    </inertial>
    <visual>
      <origin rpy="0 0 0" xyz="0.0 0.0 0.0"/>
      <geometry>
        <cylinder radius="0.04" length="0.1"/>
      </geometry>
      <material name="white_clean"/>
    </visual>
    <collision>
      <origin rpy="0 0 0" xyz="0.0 0.0 0.0"/>
      <geometry>
        <cylinder radius="0.04" length="0.1"/>
      </geometry>
    </collision>
  </link>

  <joint name="joint_2" type="revolute">
    <axis xyz="0 0 1"/>
    <parent link="ball_1"/>
    <child link="link_2"/>
    <origin xyz="0.0 0 0"/>
    <limit effort="320.0" lower="-2.0943951023931953" upper="2.0943951023931953" velocity="2.35619449019"/>
  </joint>

  <link name="link_2">
    <inertial>
      <origin rpy="0 0 0" xyz="0.24 0.0 0.0"/>
      <mass value="1"/>
      <inertia ixx="0.0008" ixy="0" ixz="0" iyy="0.0137" iyz="0" izz="0.0137"/>
    </inertial>
    <visual>
      <geometry>
        <cylinder radius="0.03" length="0.39"/>
      </geometry>
      <origin rpy="0.0 1.57079632679 0" xyz="0.24 0.0 0.0"/>
      <material name="Blue_pastel"/>
    </visual>
    <collision>
      <geometry>
        <cylinder radius="0.03" length="0.39"/>
      </geometry>
       <origin rpy="0 1.57079632679 0" xyz="0.24 0.0 0.0"/>
    </collision>
  </link>

  <joint name="fix_joint_2" type="fixed">
    <axis xyz="0 0 1"/>
    <parent link="link_2"/>
    <child link="ball_2"/>
    <origin xyz="0.48 0.0 0.0" rpy="0.0 0.0 0.0"/>
  </joint>

  <link name="ball_2">
    <inertial>
      <origin rpy="0 0 0" xyz="0.0 0.0 0.0"/>
      <mass value="1"/>
      <inertia ixx="0.0008" ixy="0" ixz="0" iyy="0.0151" iyz="0" izz="0.0151"/>
    </inertial>
    <visual>
      <origin rpy="0 0 0" xyz="0.0 0.0 0.0"/>
      <geometry>
        <cylinder radius="0.04" length="0.1"/>
      </geometry>
      <material name="white_clean"/>
    </visual>
    <collision>
      <origin rpy="0 0 0" xyz="0.0 0.0 0.0"/>
      <geometry>
        <cylinder radius="0.04" length="0.1"/>
      </geometry>
    </collision>
  </link>

  <joint name="joint_3" type="revolute">
    <axis xyz="0 0 1"/>
    <parent link="ball_2"/>
    <child link="link_3"/>
    <origin xyz="0.0 0 0"/>
    <limit effort="320.0" lower="-2.0943951023931953" upper="2.0943951023931953" velocity="2.35619449019"/>
  </joint>

  <link name="link_3">
    <inertial>
      <origin rpy="0 0 0" xyz="0.24 0.0 0.0"/>
      <mass value="1"/>
      <inertia ixx="0.0008" ixy="0" ixz="0" iyy="0.0023" iyz="0" izz="0.0023"/>
    </inertial>
    <visual>
      <geometry>
        <cylinder radius="0.03" length="0.39"/>
      </geometry>
      <origin rpy="0 1.57079632679 0" xyz="0.24 0 0"/>
      <material name="Blue_pastel"/>
    </visual>
    <collision>
      <geometry>
        <cylinder radius="0.03" length="0.39"/>
      </geometry>
      <origin rpy="0 1.57079632679 0" xyz="0.24 0.0 0.0"/>
    </collision>
  </link>

  <joint name="fix_joint_3" type="fixed">
    <axis xyz="0 0 1"/>
    <parent link="link_3"/>
    <child link="ball_3"/>
    <origin xyz="0.48 0.0 0.0" rpy="0.0 0.0 0.0"/>
  </joint>

  <link name="ball_3">
    <inertial>
      <origin rpy="0 0 0" xyz="0.0 0.0 0.0"/>
      <mass value="1"/>
      <inertia ixx="0.0008" ixy="0" ixz="0" iyy="0.0151" iyz="0" izz="0.0151"/>
    </inertial>
    <visual>
      <origin rpy="0 0 0" xyz="0.0 0.0 0.0"/>
      <geometry>
        <cylinder radius="0.04" length="0.1"/>
      </geometry>
      <material name="white_clean"/>
    </visual>
    <collision>
      <origin rpy="0 0 0" xyz="0.0 0.0 0.0"/>
      <geometry>
        <cylinder radius="0.04" length="0.1"/>
      </geometry>
    </collision>
  </link>

  <joint name="joint_4" type="revolute">
    <axis xyz="0 0 1"/>
    <parent link="ball_3"/>
    <child link="link_4"/>
    <origin xyz="0 0 0"/>
    <limit effort="320.0" lower="-2.0943951023931953" upper="2.0943951023931953" velocity="2.35619449019"/>
  </joint>

  <link name="link_4">
    <inertial>
      <origin rpy="0 0 0" xyz="0.24 0.0 0.0"/>
      <mass value="1"/>
      <inertia ixx="0.0008" ixy="0" ixz="0" iyy="0.0023" iyz="0" izz="0.0023"/>
    </inertial>
    <visual>
      <geometry>
        <cylinder radius="0.03" length="0.39"/>
      </geometry>
      <origin rpy="0 1.57079632679 0" xyz="0.24 0 0"/>
      <material name="Blue_pastel"/>
    </visual>
    <collision>
      <geometry>
        <cylinder radius="0.03" length="0.39"/>
      </geometry>
      <origin rpy="0 1.57079632679 0" xyz="0.24 0.0 0.0"/>
    </collision>
  </link>


  <joint name="fix_joint_4" type="fixed">
    <axis xyz="0 0 1"/>
    <parent link="link_4"/>
    <child link="ball_4"/>
    <origin xyz="0.48 0.0 0.0" rpy="0.0 0.0 0.0"/>
  </joint>

  <link name="ball_4">
    <inertial>
      <origin rpy="0 0 0" xyz="0.0 0.0 0.0"/>
      <mass value="1"/>
      <inertia ixx="0.0008" ixy="0" ixz="0" iyy="0.0151" iyz="0" izz="0.0151"/>
    </inertial>
    <visual>
      <origin rpy="0 0 0" xyz="0.0 0.0 0.0"/>
      <geometry>
        <cylinder radius="0.04" length="0.1"/>
      </geometry>
      <material name="white_clean"/>
    </visual>
    <collision>
      <origin rpy="0 0 0" xyz="0.0 0.0 0.0"/>
      <geometry>
        <cylinder radius="0.04" length="0.1"/>
      </geometry>
    </collision>
  </link>


  <joint name="joint_5" type="revolute">
      <axis xyz="0 0 1"/>
      <parent link="ball_4"/>
      <child link="link_5"/>
      <origin xyz="0.0 0 0.0"/>
      <limit effort="320.0" lower="-2.0943951023931953" upper="2.0943951023931953" velocity="2.35619449019"/>
  </joint>

  <link name="link_5">
    <inertial>
      <origin rpy="0 0 0" xyz="0.14 0.0 0.0"/>
      <mass value="1"/>
      <inertia ixx="0.0008" ixy="0" ixz="0" iyy="0.0023" iyz="0" izz="0.0023"/>
    </inertial>
    <visual>
      <geometry>
        <cylinder radius="0.03" length="0.18"/>
      </geometry>
      <origin rpy="0 1.57079632679 0" xyz="0.14 0 0"/>
      <material name="Blue_pastel"/>
    </visual>
    <collision>
      <geometry>
        <cylinder radius="0.03" length="0.18"/>
      </geometry>
      <origin rpy="0 1.57079632679 0" xyz="0.14 0.0 0.0"/>
    </collision>
  </link>

  <joint name="joint_ee" type="fixed">
      <axis xyz="0 0 1"/>
      <parent link="link_5"/>
      <child link="link_ee"/>
      <origin xyz="0.28 0 0"/>
  </joint>


  <link name="link_ee">
     <visual>
      <geometry>
        <sphere radius="0.03"/>
      </geometry>
      <origin rpy="0 1.57079632679 0" xyz="0.0 0 0"/>
      <material name="white_clean"/>
    </visual>
    <collision>
      <geometry>
        <sphere radius="0.03"/>
      </geometry>
      <origin rpy="0 1.57079632679 0" xyz="0.0 0 0"/>
    </collision>
  </link>


</robot>
