<?xml version="1.0" ?>
<robot name="4_link_planar">
    <link name="world" />
    <joint name="base_joint" type="fixed">
        <origin rpy="0.0 0.0 0.0" xyz="0.0 0.0 0.0" />
        <parent link="world" />
        <child link="base_link" />
    </joint>
    <link name="base_link">
        
<inertial>
            <origin rpy="0 0 0" xyz="0.0 0.0 0.0" />
            <mass value="1" />
            <inertia ixx="0.05" ixy="0" ixz="0" iyy="0.018" iyz="0" izz="0.044" />
        </inertial>

        <visual>
            <geometry>
                <sphere radius="0.1" />
            </geometry>
            <material name="black">
                <color rgba="0 0 0 1" />
            </material>
        </visual>
        <collision>
            <geometry>
                <sphere radius="0.1" />
            </geometry>
        </collision>
    </link>
    <joint name="joint_1" type="revolute">
        <axis xyz="0 0 1" />
        <parent link="base_link" />
        <child link="link_1" />
        <origin xyz="0.0 0.0 0.0" rpy="0.0 0.0 0.0" />
        <limit effort="320.0" lower="-2.9670597283903604" upper="2.9670597283903604" velocity="2.35619449019" />
    </joint>
    <link name="link_1">
        
<inertial>
            <origin rpy="0 0 0" xyz="0.3 0.0 0.0" />
            <mass value="1" />
            <inertia ixx="0.0008" ixy="0" ixz="0" iyy="0.0151" iyz="0" izz="0.0151" />
        </inertial>

        <visual>
            <origin rpy="0 1.57079632679 0" xyz="0.3 0.0 0.0" />
            <geometry>
                <cylinder radius="0.01" length="0.39" />
            </geometry>
            <material name="orange">
                <color rgba="0.8 0 0 1" />
            </material>
        </visual>
        <collision>
            <origin rpy="0 1.57079632679 0" xyz="0.3 0.0 0.0" />
            <geometry>
                <cylinder radius="0.01" length="0.39" />
            </geometry>
        </collision>
    </link>
    <joint name="joint_2" type="revolute">
        <axis xyz="0 0 1" />
        <parent link="link_1" />
        <child link="link_2" />
        <origin xyz="0.5 0 0" />
        <limit effort="320.0" lower="-2.0943951023931953" upper="2.0943951023931953" velocity="2.35619449019" />
    </joint>
    <link name="link_2">
        
<inertial>
            <origin rpy="0 0 0" xyz="0.2 0.0 0.0" />
            <mass value="1" />
            <inertia ixx="0.0008" ixy="0" ixz="0" iyy="0.0137" iyz="0" izz="0.0137" />
        </inertial>

        <visual>
            <geometry>
                <cylinder radius="0.01" length="0.39" />
            </geometry>
            <origin rpy="0.0 1.57079632679 0" xyz="0.2 0.0 0.0" />
            <material name="orange">
                <color rgba="0 0.8 0.0 1" />
            </material>
        </visual>
        <collision>
            <geometry>
                <cylinder radius="0.01" length="0.39" />
            </geometry>
            <origin rpy="0 1.57079632679 0" xyz="0.2 0.0 0.0" />
        </collision>
    </link>
    <joint name="joint_3" type="revolute">
        <axis xyz="0 0 1" />
        <parent link="link_2" />
        <child link="link_3" />
        <origin xyz="0.4 0 0" />
        <limit effort="320.0" lower="-2.0943951023931953" upper="2.0943951023931953" velocity="2.35619449019" />
    </joint>
    <link name="link_3">
        
<inertial>
            <origin rpy="0 0 0" xyz="0.2 0.0 0.0" />
            <mass value="1" />
            <inertia ixx="0.0008" ixy="0" ixz="0" iyy="0.0023" iyz="0" izz="0.0023" />
        </inertial>

        <visual>
            <geometry>
                <cylinder radius="0.01" length="0.39" />
            </geometry>
            <origin rpy="0 1.57079632679 0" xyz="0.2 0 0" />
            <material name="orange">
                <color rgba="0 0 .8 1" />
            </material>
        </visual>
        <collision>
            <geometry>
                <cylinder radius="0.01" length="0.39" />
            </geometry>
            <origin rpy="0 1.57079632679 0" xyz="0.2 0.0 0.0" />
        </collision>
    </link>
    <joint name="joint_4" type="revolute">
        <axis xyz="0 0 1" />
        <parent link="link_3" />
        <child link="link_4" />
        <origin xyz="0.4 0 0" />
        <limit effort="320.0" lower="-2.0943951023931953" upper="2.0943951023931953" velocity="2.35619449019" />
    </joint>
    <link name="link_4">
        
<inertial>
            <origin rpy="0 0 0" xyz="0.2 0.0 0.0" />
            <mass value="1" />
            <inertia ixx="0.0008" ixy="0" ixz="0" iyy="0.0023" iyz="0" izz="0.0023" />
        </inertial>

        <visual>
            <geometry>
                <cylinder radius="0.01" length="0.39" />
            </geometry>
            <origin rpy="0 1.57079632679 0" xyz="0.2 0 0" />
            <material name="orange">
                <color rgba="0 0 .3 1" />
            </material>
        </visual>
        <collision>
            <geometry>
                <cylinder radius="0.01" length="0.39" />
            </geometry>
            <origin rpy="0 1.57079632679 0" xyz="0.2 0.0 0.0" />
        </collision>
    </link>
    <joint name="joint_5" type="revolute">
        <axis xyz="0 0 1" />
        <parent link="link_4" />
        <child link="link_5" />
        <origin xyz="0.4 0 0.0" />
        <limit effort="320.0" lower="-2.0943951023931953" upper="2.0943951023931953" velocity="2.35619449019" />
    </joint>
    <link name="link_5">
        
<inertial>
            <origin rpy="0 0 0" xyz="0.05 0.0 0.0" />
            <mass value="1" />
            <inertia ixx="0.0008" ixy="0" ixz="0" iyy="0.0023" iyz="0" izz="0.0023" />
        </inertial>

        <visual>
            <geometry>
                <cylinder radius="0.01" length="0.09" />
            </geometry>
            <origin rpy="0 1.57079632679 0" xyz="0.05 0 0" />
            <material name="orange">
                <color rgba="0.3 0.3 .0 1" />
            </material>
        </visual>
        <collision>
            <geometry>
                <cylinder radius="0.01" length="0.09" />
            </geometry>
            <origin rpy="0 1.57079632679 0" xyz="0.05 0.0 0.0" />
        </collision>
    </link>
    <joint name="joint_ee" type="fixed">
        <axis xyz="0 0 1" />
        <parent link="link_5" />
        <child link="link_ee" />
        <origin xyz="0.1 0 0" />
    </joint>
    <link name="link_ee">
        <visual>
            <geometry>
                <sphere radius="0.02" />
            </geometry>
            <origin rpy="0 1.57079632679 0" xyz="0.0 0 0" />
            <material name="target">
                <color rgba="0.3 0.7 .6 1" />
            </material>
        </visual>
    </link>
    
<transmission name="trans_joint_1">
        <type>transmission_interface/SimpleTransmission</type>
        <joint name="joint_1">
            <hardwareInterface>hardware_interface/EffortJointInterface</hardwareInterface>
        </joint>
        <actuator name="joint_1_motor">
            <hardwareInterface>hardware_interface/EffortJointInterface</hardwareInterface>
            <mechanicalReduction>1</mechanicalReduction>
        </actuator>
    </transmission>
    <transmission name="trans_joint_2">
        <type>transmission_interface/SimpleTransmission</type>
        <joint name="joint_2">
            <hardwareInterface>hardware_interface/EffortJointInterface</hardwareInterface>
        </joint>
        <actuator name="joint_2_motor">
            <hardwareInterface>hardware_interface/EffortJointInterface</hardwareInterface>
            <mechanicalReduction>1</mechanicalReduction>
        </actuator>
    </transmission>
    <transmission name="trans_joint_3">
        <type>transmission_interface/SimpleTransmission</type>
        <joint name="joint_3">
            <hardwareInterface>hardware_interface/EffortJointInterface</hardwareInterface>
        </joint>
        <actuator name="joint_3_motor">
            <hardwareInterface>hardware_interface/EffortJointInterface</hardwareInterface>
            <mechanicalReduction>1</mechanicalReduction>
        </actuator>
    </transmission>
    <transmission name="trans_joint_4">
        <type>transmission_interface/SimpleTransmission</type>
        <joint name="joint_4">
            <hardwareInterface>hardware_interface/EffortJointInterface</hardwareInterface>
        </joint>
        <actuator name="joint_4_motor">
            <hardwareInterface>hardware_interface/EffortJointInterface</hardwareInterface>
            <mechanicalReduction>1</mechanicalReduction>
        </actuator>
    </transmission>
    <transmission name="trans_joint_5">
        <type>transmission_interface/SimpleTransmission</type>
        <joint name="joint_5">
            <hardwareInterface>hardware_interface/EffortJointInterface</hardwareInterface>
        </joint>
        <actuator name="joint_5_motor">
            <hardwareInterface>hardware_interface/EffortJointInterface</hardwareInterface>
            <mechanicalReduction>1</mechanicalReduction>
        </actuator>
    </transmission>
    <gazebo>
        <plugin name="gazebo_ros_control" filename="libgazebo_ros_control.so">
            <robotNamespace>/</robotNamespace>
        </plugin>
    </gazebo>
</robot>