<?xml version="1.0"?>
<robot name="se2_link_planar">
  <link name="world"/>

  <joint name="base_joint" type="fixed">
    <origin rpy="0.0 0.0 0.0" xyz="0.0 0.0 0.0"/>
    <parent link="world"/>
    <child link="base_link"/>
  </joint>

  <link name="base_link"></link>


  <joint name="joint_1" type="prismatic">
    <axis xyz="1 0 0"/>
    <parent link="base_link"/>
    <child link="link_1"/>
    <origin xyz="0.0 0.0 0.0" rpy="0.0 0.0 0.0"/>
    <limit effort="320.0" lower="-2.9670597283903604" upper="2.9670597283903604" velocity="2.35619449019"/>
  </joint>

  <link name="link_1"></link>


  <joint name="joint_2" type="prismatic">
    <axis xyz="0 1 0"/>
    <parent link="link_1"/>
    <child link="link_2"/>
    <origin xyz="0.0 0.0 0"/>
    <limit effort="320.0" lower="-2.0943951023931953" upper="2.0943951023931953" velocity="2.35619449019"/>
  </joint>

  <link name="link_2"></link>


  <joint name="joint_3" type="revolute">
    <axis xyz="0 0 1"/>
    <parent link="link_2"/>
    <child link="link_3"/>
    <origin xyz="0.0 0.0 0"/>
    <limit effort="320.0" lower="-2.0943951023931953" upper="2.0943951023931953" velocity="2.35619449019"/>
  </joint>


  <link name="link_3">
    <inertial>
      <origin rpy="0 0 0" xyz="0.15 0.0 0.0"/>
      <mass value="1"/>
      <inertia ixx="0.0008" ixy="0" ixz="0" iyy="0.0023" iyz="0" izz="0.0023"/>
    </inertial>
    <visual>
      <geometry>
        <cylinder radius="0.03" length="0.3"/>
      </geometry>
      <origin rpy="0 1.57079632679 0" xyz="0.14 0 0"/>
      <material name="orange">
        <color rgba="0.3 0.3 .0 1"/>
      </material>
    </visual>
    <collision>
      <geometry>
        <cylinder radius="0.03" length="0.3"/>
      </geometry>
      <origin rpy="0 1.57079632679 0" xyz="0.14 0.0 0.0"/>
    </collision>
  </link>

  <joint name="joint_ee" type="fixed">
      <axis xyz="0 0 1"/>
      <parent link="link_3"/>
      <child link="link_ee"/>
      <origin xyz="0.35 0 0"/>
  </joint>


  <link name="link_ee">
     <visual>
      <geometry>
        <sphere radius="0.03"/>
      </geometry>
      <origin rpy="0 1.57079632679 0" xyz="0.0 0 0"/>
      <material name="target">
        <color rgba="0.3 0.7 .6 1"/>
      </material>
    </visual>
    <collision>
      <geometry>
        <sphere radius="0.03"/>
      </geometry>
      <origin rpy="0 1.57079632679 0" xyz="0.0 0 0"/>
    </collision>
  </link>


</robot>
